[33mb'[01/Oct/2021 22:40:21] - WARNING - "GET /static/favicon.ico HTTP/1.1" 404 1792 - django.server'[0m
[33mb'[01/Oct/2021 22:46:07] - WARNING - "GET /static/ckeditor/ckeditor/plugins/styles/plugin.js?t=L4KA HTTP/1.1" 404 1892 - django.server'[0m
[33mb'[01/Oct/2021 22:46:09] - WARNING - "GET /static/ckeditor/ckeditor/plugins/styles/plugin.js?t=L4KA HTTP/1.1" 404 1892 - django.server'[0m
[33mb'[01/Oct/2021 22:46:09] - WARNING - "GET /static/ckeditor/ckeditor/plugins/styles/plugin.js?t=L4KA HTTP/1.1" 404 1892 - django.server'[0m
[33mb'[01/Oct/2021 22:46:44] - WARNING - "GET /static/ckeditor/ckeditor/plugins/styles/plugin.js?t=L4KA HTTP/1.1" 404 1892 - django.server'[0m
[33mb'[01/Oct/2021 22:46:45] - WARNING - "GET /static/ckeditor/ckeditor/plugins/styles/plugin.js?t=L4KA HTTP/1.1" 404 1892 - django.server'[0m
[33mb'[01/Oct/2021 22:46:45] - WARNING - "GET /static/ckeditor/ckeditor/plugins/styles/plugin.js?t=L4KA HTTP/1.1" 404 1892 - django.server'[0m
[33mb'[01/Oct/2021 22:46:45] - WARNING - "GET /static/ckeditor/ckeditor/plugins/styles/plugin.js?t=L4KA HTTP/1.1" 404 1892 - django.server'[0m
[33mb'[01/Oct/2021 22:46:46] - WARNING - "GET /static/ckeditor/ckeditor/plugins/styles/plugin.js?t=L4KA HTTP/1.1" 404 1892 - django.server'[0m
[33mb'[01/Oct/2021 22:46:46] - WARNING - "GET /static/ckeditor/ckeditor/plugins/styles/plugin.js?t=L4KA HTTP/1.1" 404 1892 - django.server'[0m
[33mb'[01/Oct/2021 22:47:47] - WARNING - "GET /static/ckeditor/ckeditor/plugins/styles/plugin.js?t=L4KA HTTP/1.1" 404 1892 - django.server'[0m
[33mb'[01/Oct/2021 22:47:48] - WARNING - "GET /static/ckeditor/ckeditor/plugins/styles/plugin.js?t=L4KA HTTP/1.1" 404 1892 - django.server'[0m
[33mb'[01/Oct/2021 23:04:01] - WARNING - Not Found: /media/uploads/2021/09/29/bigv164qijhutaxgbpnsdm2zyce9w58k30frlo7.jpg - django.request'[0m
[33mb'[01/Oct/2021 23:04:01] - WARNING - Not Found: /media/uploads/2021/09/29/bigv164qijhutaxgbpnsdm2zyce9w58k30frlo7.jpg - django.request'[0m
[33mb'[01/Oct/2021 23:04:01] - WARNING - "GET /media/uploads/2021/09/29/bigv164qijhutaxgbpnsdm2zyce9w58k30frlo7.jpg HTTP/1.1" 404 5694 - django.server'[0m
[33mb'[01/Oct/2021 23:04:01] - WARNING - Not Found: /media/uploads/2021/09/29/bigv164qijhutaxgbpnsdm2zyce9w58k30frlo7.jpg - django.request'[0m
[33mb'[01/Oct/2021 23:04:01] - WARNING - Not Found: /media/uploads/2021/09/29/bigv164qijhutaxgbpnsdm2zyce9w58k30frlo7.jpg - django.request'[0m
[33mb'[01/Oct/2021 23:04:01] - WARNING - "GET /media/uploads/2021/09/29/bigv164qijhutaxgbpnsdm2zyce9w58k30frlo7.jpg HTTP/1.1" 404 5694 - django.server'[0m
[33mb'[01/Oct/2021 23:04:01] - WARNING - Not Found: /media/uploads/2021/09/29/bigv164qijhutaxgbpnsdm2zyce9w58k30frlo7.jpg - django.request'[0m
[33mb'[01/Oct/2021 23:04:01] - WARNING - Not Found: /media/uploads/2021/09/29/bigv164qijhutaxgbpnsdm2zyce9w58k30frlo7.jpg - django.request'[0m
[33mb'[01/Oct/2021 23:04:01] - WARNING - "GET /media/uploads/2021/09/29/bigv164qijhutaxgbpnsdm2zyce9w58k30frlo7.jpg HTTP/1.1" 404 5694 - django.server'[0m
[33mb'[01/Oct/2021 23:04:25] - WARNING - Not Found: /media/uploads/2021/09/29/bigv164qijhutaxgbpnsdm2zyce9w58k30frlo7.jpg - django.request'[0m
[33mb'[01/Oct/2021 23:04:25] - WARNING - Not Found: /media/uploads/2021/09/29/bigv164qijhutaxgbpnsdm2zyce9w58k30frlo7.jpg - django.request'[0m
[33mb'[01/Oct/2021 23:04:25] - WARNING - "GET /media/uploads/2021/09/29/bigv164qijhutaxgbpnsdm2zyce9w58k30frlo7.jpg HTTP/1.1" 404 5694 - django.server'[0m
[33mb'[02/Oct/2021 11:13:09] - WARNING - Certificate was deleted 110212139524005 - MainApp.signals'[0m
[33mb'[02/Oct/2021 11:13:09] - WARNING - Certificate was deleted 110212139469316 - MainApp.signals'[0m
[33mb'[02/Oct/2021 11:13:09] - WARNING - Certificate was deleted 110212139423446 - MainApp.signals'[0m
[33mb'[02/Oct/2021 11:13:09] - WARNING - Certificate was deleted 110212139378295 - MainApp.signals'[0m
[33mb'[02/Oct/2021 11:13:09] - WARNING - Certificate was deleted 110212139331952 - MainApp.signals'[0m
[33mb'[02/Oct/2021 11:13:09] - WARNING - Certificate was deleted 110212139285937 - MainApp.signals'[0m
[33mb'[02/Oct/2021 11:13:09] - WARNING - Certificate was deleted 110212139590987 - MainApp.signals'[0m
[33mb'[02/Oct/2021 11:13:09] - WARNING - Certificate was deleted 110212139547555 - MainApp.signals'[0m
[33mb'[02/Oct/2021 11:13:09] - WARNING - Certificate was deleted 110212139503923 - MainApp.signals'[0m
[33mb'[02/Oct/2021 11:13:09] - WARNING - Certificate was deleted 110212139459812 - MainApp.signals'[0m
[33mb'[02/Oct/2021 11:13:09] - WARNING - Certificate was deleted 110212139416242 - MainApp.signals'[0m
[33mb'[02/Oct/2021 11:13:09] - WARNING - Certificate was deleted 110212139207189 - MainApp.signals'[0m
[33mb'[02/Oct/2021 11:13:09] - WARNING - Certificate was deleted 110212139307210 - MainApp.signals'[0m
[33mb'[02/Oct/2021 11:13:09] - WARNING - Certificate was deleted 110211950494138 - MainApp.signals'[0m
[33mb'[02/Oct/2021 11:13:09] - WARNING - Certificate was deleted 110211950531088 - MainApp.signals'[0m
[33mb'[02/Oct/2021 11:13:09] - WARNING - Certificate was deleted 110211950479775 - MainApp.signals'[0m
[33mb'[02/Oct/2021 11:13:09] - WARNING - Certificate was deleted 110211950429095 - MainApp.signals'[0m
[33mb'[02/Oct/2021 11:13:09] - WARNING - Certificate was deleted 110211950377988 - MainApp.signals'[0m
[33mb'[02/Oct/2021 11:13:09] - WARNING - Certificate was deleted 110211950325768 - MainApp.signals'[0m
[33mb'[02/Oct/2021 11:13:09] - WARNING - Certificate was deleted 110211950793672 - MainApp.signals'[0m
[33mb'[02/Oct/2021 11:13:09] - WARNING - Certificate was deleted 110211950416570 - MainApp.signals'[0m
[33mb'[02/Oct/2021 11:13:09] - WARNING - Certificate was deleted 110211950616696 - MainApp.signals'[0m
[33mb'[02/Oct/2021 11:13:09] - WARNING - Certificate was deleted 110211950572556 - MainApp.signals'[0m
[33mb'[02/Oct/2021 11:13:09] - WARNING - Certificate was deleted 110211950524636 - MainApp.signals'[0m
[33mb'[02/Oct/2021 11:13:09] - WARNING - Certificate was deleted 110211950479661 - MainApp.signals'[0m
[33mb'[02/Oct/2021 11:13:09] - WARNING - Certificate was deleted 110211950434194 - MainApp.signals'[0m
[33mb'[02/Oct/2021 11:13:09] - WARNING - Certificate was deleted 110211949749912 - MainApp.signals'[0m
[33mb'[02/Oct/2021 11:13:09] - WARNING - Certificate was deleted 110211949698032 - MainApp.signals'[0m
[33mb'[02/Oct/2021 11:13:09] - WARNING - Certificate was deleted 110211949645838 - MainApp.signals'[0m
[33mb'[02/Oct/2021 11:13:09] - WARNING - Certificate was deleted 110211949593484 - MainApp.signals'[0m
[33mb'[02/Oct/2021 11:13:09] - WARNING - Certificate was deleted 110211949540972 - MainApp.signals'[0m
[33mb'[02/Oct/2021 11:13:09] - WARNING - Certificate was deleted 110211949920434 - MainApp.signals'[0m
[33mb'[02/Oct/2021 11:13:09] - WARNING - Certificate was deleted 110211949563632 - MainApp.signals'[0m
[33mb'[02/Oct/2021 11:13:09] - WARNING - Certificate was deleted 110211111505034 - MainApp.signals'[0m
[33mb'[02/Oct/2021 11:13:09] - WARNING - Certificate was deleted 110211111454705 - MainApp.signals'[0m
[33mb'[02/Oct/2021 11:13:09] - WARNING - Certificate was deleted 110211111403301 - MainApp.signals'[0m
[33mb'[02/Oct/2021 11:13:09] - WARNING - Certificate was deleted 110211111351465 - MainApp.signals'[0m
[33mb'[02/Oct/2021 11:13:09] - WARNING - Certificate was deleted 110211111290059 - MainApp.signals'[0m
[33mb'[02/Oct/2021 11:13:09] - WARNING - Certificate was deleted 110211111120138 - MainApp.signals'[0m
[33mb'[02/Oct/2021 11:13:09] - WARNING - Certificate was deleted 110211108381944 - MainApp.signals'[0m
[33mb'[02/Oct/2021 11:13:09] - WARNING - Certificate was deleted 110211108089141 - MainApp.signals'[0m
[33mb'[02/Oct/2021 11:13:10] - WARNING - Certificate was deleted 110211108714986 - MainApp.signals'[0m
[33mb'[02/Oct/2021 11:13:10] - WARNING - Certificate was deleted 110211108012188 - MainApp.signals'[0m
[33mb'[02/Oct/2021 11:13:10] - WARNING - Certificate was deleted 110211106734753 - MainApp.signals'[0m
[33mb'[02/Oct/2021 11:13:10] - WARNING - Certificate was deleted 110211105365854 - MainApp.signals'[0m
[33mb'[02/Oct/2021 11:13:10] - WARNING - Certificate was deleted 110211059029058 - MainApp.signals'[0m
[33mb'[02/Oct/2021 11:13:10] - WARNING - Certificate was deleted 110211059976623 - MainApp.signals'[0m
[33mb'[02/Oct/2021 11:13:10] - WARNING - Certificate was deleted 110211059924702 - MainApp.signals'[0m
[33mb'[02/Oct/2021 11:13:10] - WARNING - Certificate was deleted 110211059872498 - MainApp.signals'[0m
[33mb'[02/Oct/2021 11:13:10] - WARNING - Certificate was deleted 110211059820297 - MainApp.signals'[0m
[33mb'[02/Oct/2021 11:13:10] - WARNING - Certificate was deleted 110211047974486 - MainApp.signals'[0m
[33mb'[02/Oct/2021 11:13:10] - WARNING - Certificate was deleted 110211047304530 - MainApp.signals'[0m
[31;1mb'[02/Oct/2021 15:26:07] - ERROR - Internal Server Error: /accounts/google/login/ - django.request\nTraceback (most recent call last):\n  File "/home/linux/github/MoCertsMe/venv/lib/python3.8/site-packages/django/core/handlers/exception.py", line 47, in inner\n    response = get_response(request)\n  File "/home/linux/github/MoCertsMe/venv/lib/python3.8/site-packages/django/core/handlers/base.py", line 181, in _get_response\n    response = wrapped_callback(request, *callback_args, **callback_kwargs)\n  File "/home/linux/github/MoCertsMe/venv/lib/python3.8/site-packages/allauth/socialaccount/providers/oauth2/views.py", line 77, in view\n    return self.dispatch(request, *args, **kwargs)\n  File "/home/linux/github/MoCertsMe/venv/lib/python3.8/site-packages/allauth/socialaccount/providers/oauth2/views.py", line 105, in dispatch\n    app = provider.get_app(self.request)\n  File "/home/linux/github/MoCertsMe/venv/lib/python3.8/site-packages/allauth/socialaccount/providers/base.py", line 49, in get_app\n    return adapter.get_app(request, self.id)\n  File "/home/linux/github/MoCertsMe/venv/lib/python3.8/site-packages/allauth/socialaccount/adapter.py", line 204, in get_app\n    app = SocialApp.objects.get_current(provider, request)\n  File "/home/linux/github/MoCertsMe/venv/lib/python3.8/site-packages/allauth/socialaccount/models.py", line 32, in get_current\n    app = self.get(sites__id=site.id, provider=provider)\n  File "/home/linux/github/MoCertsMe/venv/lib/python3.8/site-packages/django/db/models/manager.py", line 85, in manager_method\n    return getattr(self.get_queryset(), name)(*args, **kwargs)\n  File "/home/linux/github/MoCertsMe/venv/lib/python3.8/site-packages/django/db/models/query.py", line 435, in get\n    raise self.model.DoesNotExist(\nallauth.socialaccount.models.SocialApp.DoesNotExist: SocialApp matching query does not exist.'[0m
[31;1mb'[02/Oct/2021 15:26:07] - ERROR - Internal Server Error: /accounts/google/login/ - django.request\nTraceback (most recent call last):\n  File "/home/linux/github/MoCertsMe/venv/lib/python3.8/site-packages/django/core/handlers/exception.py", line 47, in inner\n    response = get_response(request)\n  File "/home/linux/github/MoCertsMe/venv/lib/python3.8/site-packages/django/core/handlers/base.py", line 181, in _get_response\n    response = wrapped_callback(request, *callback_args, **callback_kwargs)\n  File "/home/linux/github/MoCertsMe/venv/lib/python3.8/site-packages/allauth/socialaccount/providers/oauth2/views.py", line 77, in view\n    return self.dispatch(request, *args, **kwargs)\n  File "/home/linux/github/MoCertsMe/venv/lib/python3.8/site-packages/allauth/socialaccount/providers/oauth2/views.py", line 105, in dispatch\n    app = provider.get_app(self.request)\n  File "/home/linux/github/MoCertsMe/venv/lib/python3.8/site-packages/allauth/socialaccount/providers/base.py", line 49, in get_app\n    return adapter.get_app(request, self.id)\n  File "/home/linux/github/MoCertsMe/venv/lib/python3.8/site-packages/allauth/socialaccount/adapter.py", line 204, in get_app\n    app = SocialApp.objects.get_current(provider, request)\n  File "/home/linux/github/MoCertsMe/venv/lib/python3.8/site-packages/allauth/socialaccount/models.py", line 32, in get_current\n    app = self.get(sites__id=site.id, provider=provider)\n  File "/home/linux/github/MoCertsMe/venv/lib/python3.8/site-packages/django/db/models/manager.py", line 85, in manager_method\n    return getattr(self.get_queryset(), name)(*args, **kwargs)\n  File "/home/linux/github/MoCertsMe/venv/lib/python3.8/site-packages/django/db/models/query.py", line 435, in get\n    raise self.model.DoesNotExist(\nallauth.socialaccount.models.SocialApp.DoesNotExist: SocialApp matching query does not exist.'[0m
[31;1mb'[02/Oct/2021 15:26:07] - ERROR - "GET /accounts/google/login/ HTTP/1.1" 500 104380 - django.server'[0m
[31;1mb'[02/Oct/2021 15:29:12] - ERROR - Internal Server Error: /profile/ - django.request\nTraceback (most recent call last):\n  File "/home/linux/github/MoCertsMe/venv/lib/python3.8/site-packages/django/core/handlers/exception.py", line 47, in inner\n    response = get_response(request)\n  File "/home/linux/github/MoCertsMe/venv/lib/python3.8/site-packages/django/core/handlers/base.py", line 181, in _get_response\n    response = wrapped_callback(request, *callback_args, **callback_kwargs)\n  File "/home/linux/github/MoCertsMe/venv/lib/python3.8/site-packages/django/views/generic/base.py", line 70, in view\n    return self.dispatch(request, *args, **kwargs)\n  File "/home/linux/github/MoCertsMe/venv/lib/python3.8/site-packages/django/contrib/auth/mixins.py", line 71, in dispatch\n    return super().dispatch(request, *args, **kwargs)\n  File "/home/linux/github/MoCertsMe/venv/lib/python3.8/site-packages/django/views/generic/base.py", line 98, in dispatch\n    return handler(request, *args, **kwargs)\n  File "/home/linux/github/MoCertsMe/venv/lib/python3.8/site-packages/django/views/generic/edit.py", line 189, in get\n    self.object = self.get_object()\n  File "/home/linux/github/MoCertsMe/MoCerts/MainApp/views.py", line 58, in get_object\n    obj = CustomUser.objects.get(email=self.request.user.email)\n  File "/home/linux/github/MoCertsMe/venv/lib/python3.8/site-packages/django/db/models/manager.py", line 85, in manager_method\n    return getattr(self.get_queryset(), name)(*args, **kwargs)\n  File "/home/linux/github/MoCertsMe/venv/lib/python3.8/site-packages/django/db/models/query.py", line 439, in get\n    raise self.model.MultipleObjectsReturned(\nMainApp.models.CustomUser.MultipleObjectsReturned: get() returned more than one CustomUser -- it returned 2!'[0m
[31;1mb'[02/Oct/2021 15:29:12] - ERROR - Internal Server Error: /profile/ - django.request\nTraceback (most recent call last):\n  File "/home/linux/github/MoCertsMe/venv/lib/python3.8/site-packages/django/core/handlers/exception.py", line 47, in inner\n    response = get_response(request)\n  File "/home/linux/github/MoCertsMe/venv/lib/python3.8/site-packages/django/core/handlers/base.py", line 181, in _get_response\n    response = wrapped_callback(request, *callback_args, **callback_kwargs)\n  File "/home/linux/github/MoCertsMe/venv/lib/python3.8/site-packages/django/views/generic/base.py", line 70, in view\n    return self.dispatch(request, *args, **kwargs)\n  File "/home/linux/github/MoCertsMe/venv/lib/python3.8/site-packages/django/contrib/auth/mixins.py", line 71, in dispatch\n    return super().dispatch(request, *args, **kwargs)\n  File "/home/linux/github/MoCertsMe/venv/lib/python3.8/site-packages/django/views/generic/base.py", line 98, in dispatch\n    return handler(request, *args, **kwargs)\n  File "/home/linux/github/MoCertsMe/venv/lib/python3.8/site-packages/django/views/generic/edit.py", line 189, in get\n    self.object = self.get_object()\n  File "/home/linux/github/MoCertsMe/MoCerts/MainApp/views.py", line 58, in get_object\n    obj = CustomUser.objects.get(email=self.request.user.email)\n  File "/home/linux/github/MoCertsMe/venv/lib/python3.8/site-packages/django/db/models/manager.py", line 85, in manager_method\n    return getattr(self.get_queryset(), name)(*args, **kwargs)\n  File "/home/linux/github/MoCertsMe/venv/lib/python3.8/site-packages/django/db/models/query.py", line 439, in get\n    raise self.model.MultipleObjectsReturned(\nMainApp.models.CustomUser.MultipleObjectsReturned: get() returned more than one CustomUser -- it returned 2!'[0m
[31;1mb'[02/Oct/2021 15:29:12] - ERROR - "GET /profile/ HTTP/1.1" 500 105184 - django.server'[0m
[31;1mb'[02/Oct/2021 15:29:22] - ERROR - Internal Server Error: /profile/ - django.request\nTraceback (most recent call last):\n  File "/home/linux/github/MoCertsMe/venv/lib/python3.8/site-packages/django/core/handlers/exception.py", line 47, in inner\n    response = get_response(request)\n  File "/home/linux/github/MoCertsMe/venv/lib/python3.8/site-packages/django/core/handlers/base.py", line 181, in _get_response\n    response = wrapped_callback(request, *callback_args, **callback_kwargs)\n  File "/home/linux/github/MoCertsMe/venv/lib/python3.8/site-packages/django/views/generic/base.py", line 70, in view\n    return self.dispatch(request, *args, **kwargs)\n  File "/home/linux/github/MoCertsMe/venv/lib/python3.8/site-packages/django/contrib/auth/mixins.py", line 71, in dispatch\n    return super().dispatch(request, *args, **kwargs)\n  File "/home/linux/github/MoCertsMe/venv/lib/python3.8/site-packages/django/views/generic/base.py", line 98, in dispatch\n    return handler(request, *args, **kwargs)\n  File "/home/linux/github/MoCertsMe/venv/lib/python3.8/site-packages/django/views/generic/edit.py", line 189, in get\n    self.object = self.get_object()\n  File "/home/linux/github/MoCertsMe/MoCerts/MainApp/views.py", line 58, in get_object\n    obj = CustomUser.objects.get(email=self.request.user.email)\n  File "/home/linux/github/MoCertsMe/venv/lib/python3.8/site-packages/django/db/models/manager.py", line 85, in manager_method\n    return getattr(self.get_queryset(), name)(*args, **kwargs)\n  File "/home/linux/github/MoCertsMe/venv/lib/python3.8/site-packages/django/db/models/query.py", line 439, in get\n    raise self.model.MultipleObjectsReturned(\nMainApp.models.CustomUser.MultipleObjectsReturned: get() returned more than one CustomUser -- it returned 2!'[0m
[31;1mb'[02/Oct/2021 15:29:22] - ERROR - Internal Server Error: /profile/ - django.request\nTraceback (most recent call last):\n  File "/home/linux/github/MoCertsMe/venv/lib/python3.8/site-packages/django/core/handlers/exception.py", line 47, in inner\n    response = get_response(request)\n  File "/home/linux/github/MoCertsMe/venv/lib/python3.8/site-packages/django/core/handlers/base.py", line 181, in _get_response\n    response = wrapped_callback(request, *callback_args, **callback_kwargs)\n  File "/home/linux/github/MoCertsMe/venv/lib/python3.8/site-packages/django/views/generic/base.py", line 70, in view\n    return self.dispatch(request, *args, **kwargs)\n  File "/home/linux/github/MoCertsMe/venv/lib/python3.8/site-packages/django/contrib/auth/mixins.py", line 71, in dispatch\n    return super().dispatch(request, *args, **kwargs)\n  File "/home/linux/github/MoCertsMe/venv/lib/python3.8/site-packages/django/views/generic/base.py", line 98, in dispatch\n    return handler(request, *args, **kwargs)\n  File "/home/linux/github/MoCertsMe/venv/lib/python3.8/site-packages/django/views/generic/edit.py", line 189, in get\n    self.object = self.get_object()\n  File "/home/linux/github/MoCertsMe/MoCerts/MainApp/views.py", line 58, in get_object\n    obj = CustomUser.objects.get(email=self.request.user.email)\n  File "/home/linux/github/MoCertsMe/venv/lib/python3.8/site-packages/django/db/models/manager.py", line 85, in manager_method\n    return getattr(self.get_queryset(), name)(*args, **kwargs)\n  File "/home/linux/github/MoCertsMe/venv/lib/python3.8/site-packages/django/db/models/query.py", line 439, in get\n    raise self.model.MultipleObjectsReturned(\nMainApp.models.CustomUser.MultipleObjectsReturned: get() returned more than one CustomUser -- it returned 2!'[0m
[31;1mb'[02/Oct/2021 15:29:22] - ERROR - "GET /profile/ HTTP/1.1" 500 105039 - django.server'[0m
[31;1mb'[02/Oct/2021 15:30:26] - ERROR - Connection to Redis lost: Retry (0/20) now. - celery.backends.redis'[0m
[31;1mb'[02/Oct/2021 15:30:26] - ERROR - Connection to Redis lost: Retry (1/20) in 1.00 second. - celery.backends.redis'[0m
[31;1mb'[02/Oct/2021 15:30:27] - ERROR - Connection to Redis lost: Retry (2/20) in 1.00 second. - celery.backends.redis'[0m
[31;1mb'[02/Oct/2021 15:30:28] - ERROR - Connection to Redis lost: Retry (3/20) in 1.00 second. - celery.backends.redis'[0m
[31;1mb'[02/Oct/2021 15:30:29] - ERROR - Connection to Redis lost: Retry (4/20) in 1.00 second. - celery.backends.redis'[0m
[31;1mb'[02/Oct/2021 15:30:30] - ERROR - Connection to Redis lost: Retry (5/20) in 1.00 second. - celery.backends.redis'[0m
[31;1mb'[02/Oct/2021 15:30:31] - ERROR - Connection to Redis lost: Retry (6/20) in 1.00 second. - celery.backends.redis'[0m
[31;1mb'[02/Oct/2021 15:30:32] - ERROR - Connection to Redis lost: Retry (7/20) in 1.00 second. - celery.backends.redis'[0m
[31;1mb'[02/Oct/2021 15:30:33] - ERROR - Connection to Redis lost: Retry (8/20) in 1.00 second. - celery.backends.redis'[0m
[31;1mb'[02/Oct/2021 15:30:34] - ERROR - Connection to Redis lost: Retry (9/20) in 1.00 second. - celery.backends.redis'[0m
[31;1mb'[02/Oct/2021 15:30:35] - ERROR - Connection to Redis lost: Retry (10/20) in 1.00 second. - celery.backends.redis'[0m
[31;1mb'[02/Oct/2021 15:30:36] - ERROR - Connection to Redis lost: Retry (11/20) in 1.00 second. - celery.backends.redis'[0m
[33mb'[02/Oct/2021 16:42:19] - WARNING - "GET /static/js/swiper-bundle.min.js HTTP/1.1" 404 1828 - django.server'[0m
[33mb'[02/Oct/2021 16:42:21] - WARNING - "GET /static/js/swiper-bundle.min.js HTTP/1.1" 404 1828 - django.server'[0m
[33mb'[02/Oct/2021 16:42:21] - WARNING - "GET /static/js/swiper-bundle.min.js HTTP/1.1" 404 1828 - django.server'[0m
[33mb'[02/Oct/2021 16:43:25] - WARNING - "GET /static/js/swiper-bundle.min.js HTTP/1.1" 404 1828 - django.server'[0m
[33mb'[02/Oct/2021 16:43:25] - WARNING - "GET /static/js/swiper-bundle.min.js HTTP/1.1" 404 1828 - django.server'[0m
[33mb'[02/Oct/2021 16:43:28] - WARNING - "GET /static/js/swiper-bundle.min.js HTTP/1.1" 404 1828 - django.server'[0m
[33mb'[02/Oct/2021 16:43:28] - WARNING - "GET /static/js/swiper-bundle.min.js HTTP/1.1" 404 1828 - django.server'[0m
[33mb'[02/Oct/2021 16:47:04] - WARNING - "GET /static/js/swiper-bundle.min.js HTTP/1.1" 404 1828 - django.server'[0m
[33mb'[02/Oct/2021 16:47:04] - WARNING - "GET /static/js/swiper-bundle.min.js HTTP/1.1" 404 1828 - django.server'[0m
[33mb'[02/Oct/2021 16:47:06] - WARNING - "GET /static/js/swiper-bundle.min.js HTTP/1.1" 404 1828 - django.server'[0m
[33mb'[02/Oct/2021 16:47:07] - WARNING - "GET /static/js/swiper-bundle.min.js HTTP/1.1" 404 1828 - django.server'[0m
[33mb'[02/Oct/2021 16:47:07] - WARNING - "GET /static/js/swiper-bundle.min.js HTTP/1.1" 404 1828 - django.server'[0m
[33mb'[02/Oct/2021 16:47:15] - WARNING - "GET /static/js/swiper-bundle.min.js HTTP/1.1" 404 1828 - django.server'[0m
[33mb'[02/Oct/2021 16:47:15] - WARNING - "GET /static/js/swiper-bundle.min.js HTTP/1.1" 404 1828 - django.server'[0m
[33mb'[02/Oct/2021 16:51:30] - WARNING - "GET /static/swiper/swiper-bundle.min.js.map HTTP/1.1" 404 1852 - django.server'[0m
[33mb'[02/Oct/2021 16:51:48] - WARNING - "GET /static/swiper/swiper-bundle.min.js.map HTTP/1.1" 404 1852 - django.server'[0m
[33mb'[02/Oct/2021 16:52:57] - WARNING - "GET /static/swiper/swiper-bundle.min.js.map HTTP/1.1" 404 1852 - django.server'[0m
[31;1mb'[02/Oct/2021 18:48:10] - ERROR - Connection to Redis lost: Retry (0/20) now. - celery.backends.redis'[0m
[31;1mb'[02/Oct/2021 18:48:10] - ERROR - Connection to Redis lost: Retry (1/20) in 1.00 second. - celery.backends.redis'[0m
[31;1mb'[02/Oct/2021 18:48:11] - ERROR - Connection to Redis lost: Retry (2/20) in 1.00 second. - celery.backends.redis'[0m
[31;1mb'[02/Oct/2021 18:48:12] - ERROR - Connection to Redis lost: Retry (3/20) in 1.00 second. - celery.backends.redis'[0m
[31;1mb'[02/Oct/2021 18:48:13] - ERROR - Connection to Redis lost: Retry (4/20) in 1.00 second. - celery.backends.redis'[0m
[31;1mb'[02/Oct/2021 18:48:14] - ERROR - Connection to Redis lost: Retry (5/20) in 1.00 second. - celery.backends.redis'[0m
[31;1mb'[02/Oct/2021 18:48:15] - ERROR - Connection to Redis lost: Retry (6/20) in 1.00 second. - celery.backends.redis'[0m
[31;1mb'[02/Oct/2021 18:48:16] - ERROR - Connection to Redis lost: Retry (7/20) in 1.00 second. - celery.backends.redis'[0m
[31;1mb'[02/Oct/2021 18:48:17] - ERROR - Connection to Redis lost: Retry (8/20) in 1.00 second. - celery.backends.redis'[0m
[31;1mb'[02/Oct/2021 18:48:18] - ERROR - Connection to Redis lost: Retry (9/20) in 1.00 second. - celery.backends.redis'[0m
[31;1mb'[02/Oct/2021 18:48:19] - ERROR - Connection to Redis lost: Retry (10/20) in 1.00 second. - celery.backends.redis'[0m
[31;1mb'[02/Oct/2021 18:48:20] - ERROR - Connection to Redis lost: Retry (11/20) in 1.00 second. - celery.backends.redis'[0m
[31;1mb'[02/Oct/2021 18:48:21] - ERROR - Connection to Redis lost: Retry (12/20) in 1.00 second. - celery.backends.redis'[0m
[31;1mb'[02/Oct/2021 19:07:41] - ERROR - Internal Server Error: /nimda/MainApp/manualposts/6/change/ - django.request\nTraceback (most recent call last):\n  File "/home/linux/github/MoCertsMe/venv/lib/python3.8/site-packages/django/core/handlers/exception.py", line 47, in inner\n    response = get_response(request)\n  File "/home/linux/github/MoCertsMe/venv/lib/python3.8/site-packages/django/core/handlers/base.py", line 181, in _get_response\n    response = wrapped_callback(request, *callback_args, **callback_kwargs)\n  File "/home/linux/github/MoCertsMe/venv/lib/python3.8/site-packages/django/contrib/admin/options.py", line 616, in wrapper\n    return self.admin_site.admin_view(view)(*args, **kwargs)\n  File "/home/linux/github/MoCertsMe/venv/lib/python3.8/site-packages/django/utils/decorators.py", line 130, in _wrapped_view\n    response = view_func(request, *args, **kwargs)\n  File "/home/linux/github/MoCertsMe/venv/lib/python3.8/site-packages/django/views/decorators/cache.py", line 44, in _wrapped_view_func\n    response = view_func(request, *args, **kwargs)\n  File "/home/linux/github/MoCertsMe/venv/lib/python3.8/site-packages/django/contrib/admin/sites.py", line 232, in inner\n    return view(request, *args, **kwargs)\n  File "/home/linux/github/MoCertsMe/venv/lib/python3.8/site-packages/django/contrib/admin/options.py", line 1660, in change_view\n    return self.changeform_view(request, object_id, form_url, extra_context)\n  File "/home/linux/github/MoCertsMe/venv/lib/python3.8/site-packages/django/utils/decorators.py", line 43, in _wrapper\n    return bound_method(*args, **kwargs)\n  File "/home/linux/github/MoCertsMe/venv/lib/python3.8/site-packages/django/utils/decorators.py", line 130, in _wrapped_view\n    response = view_func(request, *args, **kwargs)\n  File "/home/linux/github/MoCertsMe/venv/lib/python3.8/site-packages/django/contrib/admin/options.py", line 1540, in changeform_view\n    return self._changeform_view(request, object_id, form_url, extra_context)\n  File "/home/linux/github/MoCertsMe/venv/lib/python3.8/site-packages/django/contrib/admin/options.py", line 1579, in _changeform_view\n    form_validated = form.is_valid()\n  File "/home/linux/github/MoCertsMe/venv/lib/python3.8/site-packages/django/forms/forms.py", line 175, in is_valid\n    return self.is_bound and not self.errors\n  File "/home/linux/github/MoCertsMe/venv/lib/python3.8/site-packages/django/forms/forms.py", line 170, in errors\n    self.full_clean()\n  File "/home/linux/github/MoCertsMe/venv/lib/python3.8/site-packages/django/forms/forms.py", line 374, in full_clean\n    self._post_clean()\n  File "/home/linux/github/MoCertsMe/venv/lib/python3.8/site-packages/django/forms/models.py", line 413, in _post_clean\n    self.instance.full_clean(exclude=exclude, validate_unique=False)\n  File "/home/linux/github/MoCertsMe/venv/lib/python3.8/site-packages/django/db/models/base.py", line 1223, in full_clean\n    self.clean()\n  File "/home/linux/github/MoCertsMe/MoCerts/MainApp/models.py", line 143, in clean\n    if manual_object.exists() and manual_object.index_number != self.index_number:\nAttributeError: \'QuerySet\' object has no attribute \'index_number\''[0m
[31;1mb'[02/Oct/2021 19:07:41] - ERROR - Internal Server Error: /nimda/MainApp/manualposts/6/change/ - django.request\nTraceback (most recent call last):\n  File "/home/linux/github/MoCertsMe/venv/lib/python3.8/site-packages/django/core/handlers/exception.py", line 47, in inner\n    response = get_response(request)\n  File "/home/linux/github/MoCertsMe/venv/lib/python3.8/site-packages/django/core/handlers/base.py", line 181, in _get_response\n    response = wrapped_callback(request, *callback_args, **callback_kwargs)\n  File "/home/linux/github/MoCertsMe/venv/lib/python3.8/site-packages/django/contrib/admin/options.py", line 616, in wrapper\n    return self.admin_site.admin_view(view)(*args, **kwargs)\n  File "/home/linux/github/MoCertsMe/venv/lib/python3.8/site-packages/django/utils/decorators.py", line 130, in _wrapped_view\n    response = view_func(request, *args, **kwargs)\n  File "/home/linux/github/MoCertsMe/venv/lib/python3.8/site-packages/django/views/decorators/cache.py", line 44, in _wrapped_view_func\n    response = view_func(request, *args, **kwargs)\n  File "/home/linux/github/MoCertsMe/venv/lib/python3.8/site-packages/django/contrib/admin/sites.py", line 232, in inner\n    return view(request, *args, **kwargs)\n  File "/home/linux/github/MoCertsMe/venv/lib/python3.8/site-packages/django/contrib/admin/options.py", line 1660, in change_view\n    return self.changeform_view(request, object_id, form_url, extra_context)\n  File "/home/linux/github/MoCertsMe/venv/lib/python3.8/site-packages/django/utils/decorators.py", line 43, in _wrapper\n    return bound_method(*args, **kwargs)\n  File "/home/linux/github/MoCertsMe/venv/lib/python3.8/site-packages/django/utils/decorators.py", line 130, in _wrapped_view\n    response = view_func(request, *args, **kwargs)\n  File "/home/linux/github/MoCertsMe/venv/lib/python3.8/site-packages/django/contrib/admin/options.py", line 1540, in changeform_view\n    return self._changeform_view(request, object_id, form_url, extra_context)\n  File "/home/linux/github/MoCertsMe/venv/lib/python3.8/site-packages/django/contrib/admin/options.py", line 1579, in _changeform_view\n    form_validated = form.is_valid()\n  File "/home/linux/github/MoCertsMe/venv/lib/python3.8/site-packages/django/forms/forms.py", line 175, in is_valid\n    return self.is_bound and not self.errors\n  File "/home/linux/github/MoCertsMe/venv/lib/python3.8/site-packages/django/forms/forms.py", line 170, in errors\n    self.full_clean()\n  File "/home/linux/github/MoCertsMe/venv/lib/python3.8/site-packages/django/forms/forms.py", line 374, in full_clean\n    self._post_clean()\n  File "/home/linux/github/MoCertsMe/venv/lib/python3.8/site-packages/django/forms/models.py", line 413, in _post_clean\n    self.instance.full_clean(exclude=exclude, validate_unique=False)\n  File "/home/linux/github/MoCertsMe/venv/lib/python3.8/site-packages/django/db/models/base.py", line 1223, in full_clean\n    self.clean()\n  File "/home/linux/github/MoCertsMe/MoCerts/MainApp/models.py", line 143, in clean\n    if manual_object.exists() and manual_object.index_number != self.index_number:\nAttributeError: \'QuerySet\' object has no attribute \'index_number\''[0m
[31;1mb'[02/Oct/2021 19:07:41] - ERROR - "POST /nimda/MainApp/manualposts/6/change/ HTTP/1.1" 500 144717 - django.server'[0m
[33mb'[04/Oct/2021 21:01:09] - WARNING - Not Found: /blog - django.request'[0m
[33mb'[04/Oct/2021 21:01:09] - WARNING - Not Found: /blog - django.request'[0m
[33mb'[04/Oct/2021 21:01:09] - WARNING - "GET /blog HTTP/1.1" 404 5072 - django.server'[0m
[31;1mb'[04/Oct/2021 21:01:13] - ERROR - Internal Server Error: / - django.request\nTraceback (most recent call last):\n  File "/home/linux/github/MoCertsMe/venv/lib/python3.8/site-packages/django/core/handlers/exception.py", line 47, in inner\n    response = get_response(request)\n  File "/home/linux/github/MoCertsMe/venv/lib/python3.8/site-packages/django/core/handlers/base.py", line 204, in _get_response\n    response = response.render()\n  File "/home/linux/github/MoCertsMe/venv/lib/python3.8/site-packages/django/template/response.py", line 105, in render\n    self.content = self.rendered_content\n  File "/home/linux/github/MoCertsMe/venv/lib/python3.8/site-packages/django/template/response.py", line 83, in rendered_content\n    return template.render(context, self._request)\n  File "/home/linux/github/MoCertsMe/venv/lib/python3.8/site-packages/django/template/backends/django.py", line 61, in render\n    return self.template.render(context)\n  File "/home/linux/github/MoCertsMe/venv/lib/python3.8/site-packages/django/template/base.py", line 170, in render\n    return self._render(context)\n  File "/home/linux/github/MoCertsMe/venv/lib/python3.8/site-packages/django/template/base.py", line 162, in _render\n    return self.nodelist.render(context)\n  File "/home/linux/github/MoCertsMe/venv/lib/python3.8/site-packages/django/template/base.py", line 938, in render\n    bit = node.render_annotated(context)\n  File "/home/linux/github/MoCertsMe/venv/lib/python3.8/site-packages/django/template/base.py", line 905, in render_annotated\n    return self.render(context)\n  File "/home/linux/github/MoCertsMe/venv/lib/python3.8/site-packages/django/template/loader_tags.py", line 150, in render\n    return compiled_parent._render(context)\n  File "/home/linux/github/MoCertsMe/venv/lib/python3.8/site-packages/django/template/base.py", line 162, in _render\n    return self.nodelist.render(context)\n  File "/home/linux/github/MoCertsMe/venv/lib/python3.8/site-packages/django/template/base.py", line 938, in render\n    bit = node.render_annotated(context)\n  File "/home/linux/github/MoCertsMe/venv/lib/python3.8/site-packages/django/template/base.py", line 905, in render_annotated\n    return self.render(context)\n  File "/home/linux/github/MoCertsMe/venv/lib/python3.8/site-packages/django/template/defaulttags.py", line 312, in render\n    return nodelist.render(context)\n  File "/home/linux/github/MoCertsMe/venv/lib/python3.8/site-packages/django/template/base.py", line 938, in render\n    bit = node.render_annotated(context)\n  File "/home/linux/github/MoCertsMe/venv/lib/python3.8/site-packages/django/template/base.py", line 905, in render_annotated\n    return self.render(context)\n  File "/home/linux/github/MoCertsMe/venv/lib/python3.8/site-packages/django/template/defaulttags.py", line 446, in render\n    url = reverse(view_name, args=args, kwargs=kwargs, current_app=current_app)\n  File "/home/linux/github/MoCertsMe/venv/lib/python3.8/site-packages/django/urls/base.py", line 86, in reverse\n    return resolver._reverse_with_prefix(view, prefix, *args, **kwargs)\n  File "/home/linux/github/MoCertsMe/venv/lib/python3.8/site-packages/django/urls/resolvers.py", line 694, in _reverse_with_prefix\n    raise NoReverseMatch(msg)\ndjango.urls.exceptions.NoReverseMatch: Reverse for \'blog\' not found. \'blog\' is not a valid view function or pattern name.'[0m
[31;1mb'[04/Oct/2021 21:01:13] - ERROR - Internal Server Error: / - django.request\nTraceback (most recent call last):\n  File "/home/linux/github/MoCertsMe/venv/lib/python3.8/site-packages/django/core/handlers/exception.py", line 47, in inner\n    response = get_response(request)\n  File "/home/linux/github/MoCertsMe/venv/lib/python3.8/site-packages/django/core/handlers/base.py", line 204, in _get_response\n    response = response.render()\n  File "/home/linux/github/MoCertsMe/venv/lib/python3.8/site-packages/django/template/response.py", line 105, in render\n    self.content = self.rendered_content\n  File "/home/linux/github/MoCertsMe/venv/lib/python3.8/site-packages/django/template/response.py", line 83, in rendered_content\n    return template.render(context, self._request)\n  File "/home/linux/github/MoCertsMe/venv/lib/python3.8/site-packages/django/template/backends/django.py", line 61, in render\n    return self.template.render(context)\n  File "/home/linux/github/MoCertsMe/venv/lib/python3.8/site-packages/django/template/base.py", line 170, in render\n    return self._render(context)\n  File "/home/linux/github/MoCertsMe/venv/lib/python3.8/site-packages/django/template/base.py", line 162, in _render\n    return self.nodelist.render(context)\n  File "/home/linux/github/MoCertsMe/venv/lib/python3.8/site-packages/django/template/base.py", line 938, in render\n    bit = node.render_annotated(context)\n  File "/home/linux/github/MoCertsMe/venv/lib/python3.8/site-packages/django/template/base.py", line 905, in render_annotated\n    return self.render(context)\n  File "/home/linux/github/MoCertsMe/venv/lib/python3.8/site-packages/django/template/loader_tags.py", line 150, in render\n    return compiled_parent._render(context)\n  File "/home/linux/github/MoCertsMe/venv/lib/python3.8/site-packages/django/template/base.py", line 162, in _render\n    return self.nodelist.render(context)\n  File "/home/linux/github/MoCertsMe/venv/lib/python3.8/site-packages/django/template/base.py", line 938, in render\n    bit = node.render_annotated(context)\n  File "/home/linux/github/MoCertsMe/venv/lib/python3.8/site-packages/django/template/base.py", line 905, in render_annotated\n    return self.render(context)\n  File "/home/linux/github/MoCertsMe/venv/lib/python3.8/site-packages/django/template/defaulttags.py", line 312, in render\n    return nodelist.render(context)\n  File "/home/linux/github/MoCertsMe/venv/lib/python3.8/site-packages/django/template/base.py", line 938, in render\n    bit = node.render_annotated(context)\n  File "/home/linux/github/MoCertsMe/venv/lib/python3.8/site-packages/django/template/base.py", line 905, in render_annotated\n    return self.render(context)\n  File "/home/linux/github/MoCertsMe/venv/lib/python3.8/site-packages/django/template/defaulttags.py", line 446, in render\n    url = reverse(view_name, args=args, kwargs=kwargs, current_app=current_app)\n  File "/home/linux/github/MoCertsMe/venv/lib/python3.8/site-packages/django/urls/base.py", line 86, in reverse\n    return resolver._reverse_with_prefix(view, prefix, *args, **kwargs)\n  File "/home/linux/github/MoCertsMe/venv/lib/python3.8/site-packages/django/urls/resolvers.py", line 694, in _reverse_with_prefix\n    raise NoReverseMatch(msg)\ndjango.urls.exceptions.NoReverseMatch: Reverse for \'blog\' not found. \'blog\' is not a valid view function or pattern name.'[0m
[31;1mb'[04/Oct/2021 21:01:13] - ERROR - "GET / HTTP/1.1" 500 176631 - django.server'[0m
[31;1mb'[04/Oct/2021 21:01:15] - ERROR - Internal Server Error: / - django.request\nTraceback (most recent call last):\n  File "/home/linux/github/MoCertsMe/venv/lib/python3.8/site-packages/django/core/handlers/exception.py", line 47, in inner\n    response = get_response(request)\n  File "/home/linux/github/MoCertsMe/venv/lib/python3.8/site-packages/django/core/handlers/base.py", line 204, in _get_response\n    response = response.render()\n  File "/home/linux/github/MoCertsMe/venv/lib/python3.8/site-packages/django/template/response.py", line 105, in render\n    self.content = self.rendered_content\n  File "/home/linux/github/MoCertsMe/venv/lib/python3.8/site-packages/django/template/response.py", line 83, in rendered_content\n    return template.render(context, self._request)\n  File "/home/linux/github/MoCertsMe/venv/lib/python3.8/site-packages/django/template/backends/django.py", line 61, in render\n    return self.template.render(context)\n  File "/home/linux/github/MoCertsMe/venv/lib/python3.8/site-packages/django/template/base.py", line 170, in render\n    return self._render(context)\n  File "/home/linux/github/MoCertsMe/venv/lib/python3.8/site-packages/django/template/base.py", line 162, in _render\n    return self.nodelist.render(context)\n  File "/home/linux/github/MoCertsMe/venv/lib/python3.8/site-packages/django/template/base.py", line 938, in render\n    bit = node.render_annotated(context)\n  File "/home/linux/github/MoCertsMe/venv/lib/python3.8/site-packages/django/template/base.py", line 905, in render_annotated\n    return self.render(context)\n  File "/home/linux/github/MoCertsMe/venv/lib/python3.8/site-packages/django/template/loader_tags.py", line 150, in render\n    return compiled_parent._render(context)\n  File "/home/linux/github/MoCertsMe/venv/lib/python3.8/site-packages/django/template/base.py", line 162, in _render\n    return self.nodelist.render(context)\n  File "/home/linux/github/MoCertsMe/venv/lib/python3.8/site-packages/django/template/base.py", line 938, in render\n    bit = node.render_annotated(context)\n  File "/home/linux/github/MoCertsMe/venv/lib/python3.8/site-packages/django/template/base.py", line 905, in render_annotated\n    return self.render(context)\n  File "/home/linux/github/MoCertsMe/venv/lib/python3.8/site-packages/django/template/defaulttags.py", line 312, in render\n    return nodelist.render(context)\n  File "/home/linux/github/MoCertsMe/venv/lib/python3.8/site-packages/django/template/base.py", line 938, in render\n    bit = node.render_annotated(context)\n  File "/home/linux/github/MoCertsMe/venv/lib/python3.8/site-packages/django/template/base.py", line 905, in render_annotated\n    return self.render(context)\n  File "/home/linux/github/MoCertsMe/venv/lib/python3.8/site-packages/django/template/defaulttags.py", line 446, in render\n    url = reverse(view_name, args=args, kwargs=kwargs, current_app=current_app)\n  File "/home/linux/github/MoCertsMe/venv/lib/python3.8/site-packages/django/urls/base.py", line 86, in reverse\n    return resolver._reverse_with_prefix(view, prefix, *args, **kwargs)\n  File "/home/linux/github/MoCertsMe/venv/lib/python3.8/site-packages/django/urls/resolvers.py", line 694, in _reverse_with_prefix\n    raise NoReverseMatch(msg)\ndjango.urls.exceptions.NoReverseMatch: Reverse for \'blog\' not found. \'blog\' is not a valid view function or pattern name.'[0m
[31;1mb'[04/Oct/2021 21:01:15] - ERROR - Internal Server Error: / - django.request\nTraceback (most recent call last):\n  File "/home/linux/github/MoCertsMe/venv/lib/python3.8/site-packages/django/core/handlers/exception.py", line 47, in inner\n    response = get_response(request)\n  File "/home/linux/github/MoCertsMe/venv/lib/python3.8/site-packages/django/core/handlers/base.py", line 204, in _get_response\n    response = response.render()\n  File "/home/linux/github/MoCertsMe/venv/lib/python3.8/site-packages/django/template/response.py", line 105, in render\n    self.content = self.rendered_content\n  File "/home/linux/github/MoCertsMe/venv/lib/python3.8/site-packages/django/template/response.py", line 83, in rendered_content\n    return template.render(context, self._request)\n  File "/home/linux/github/MoCertsMe/venv/lib/python3.8/site-packages/django/template/backends/django.py", line 61, in render\n    return self.template.render(context)\n  File "/home/linux/github/MoCertsMe/venv/lib/python3.8/site-packages/django/template/base.py", line 170, in render\n    return self._render(context)\n  File "/home/linux/github/MoCertsMe/venv/lib/python3.8/site-packages/django/template/base.py", line 162, in _render\n    return self.nodelist.render(context)\n  File "/home/linux/github/MoCertsMe/venv/lib/python3.8/site-packages/django/template/base.py", line 938, in render\n    bit = node.render_annotated(context)\n  File "/home/linux/github/MoCertsMe/venv/lib/python3.8/site-packages/django/template/base.py", line 905, in render_annotated\n    return self.render(context)\n  File "/home/linux/github/MoCertsMe/venv/lib/python3.8/site-packages/django/template/loader_tags.py", line 150, in render\n    return compiled_parent._render(context)\n  File "/home/linux/github/MoCertsMe/venv/lib/python3.8/site-packages/django/template/base.py", line 162, in _render\n    return self.nodelist.render(context)\n  File "/home/linux/github/MoCertsMe/venv/lib/python3.8/site-packages/django/template/base.py", line 938, in render\n    bit = node.render_annotated(context)\n  File "/home/linux/github/MoCertsMe/venv/lib/python3.8/site-packages/django/template/base.py", line 905, in render_annotated\n    return self.render(context)\n  File "/home/linux/github/MoCertsMe/venv/lib/python3.8/site-packages/django/template/defaulttags.py", line 312, in render\n    return nodelist.render(context)\n  File "/home/linux/github/MoCertsMe/venv/lib/python3.8/site-packages/django/template/base.py", line 938, in render\n    bit = node.render_annotated(context)\n  File "/home/linux/github/MoCertsMe/venv/lib/python3.8/site-packages/django/template/base.py", line 905, in render_annotated\n    return self.render(context)\n  File "/home/linux/github/MoCertsMe/venv/lib/python3.8/site-packages/django/template/defaulttags.py", line 446, in render\n    url = reverse(view_name, args=args, kwargs=kwargs, current_app=current_app)\n  File "/home/linux/github/MoCertsMe/venv/lib/python3.8/site-packages/django/urls/base.py", line 86, in reverse\n    return resolver._reverse_with_prefix(view, prefix, *args, **kwargs)\n  File "/home/linux/github/MoCertsMe/venv/lib/python3.8/site-packages/django/urls/resolvers.py", line 694, in _reverse_with_prefix\n    raise NoReverseMatch(msg)\ndjango.urls.exceptions.NoReverseMatch: Reverse for \'blog\' not found. \'blog\' is not a valid view function or pattern name.'[0m
[31;1mb'[04/Oct/2021 21:01:15] - ERROR - "GET / HTTP/1.1" 500 176768 - django.server'[0m
